<mujoco model="aligeno">
    <compiler angle="radian" meshdir="meshes"/>
    <size njmax="5000" nconmax="10000"/>

    <default>
        <light castshadow="false" diffuse="1 1 1"/>
        <camera fovy="60"/>
        <default class="visual">
            <geom contype="0" conaffinity="0" group="1" type="mesh" rgba="0.9 0.9 0.9 1.0"/>
        </default>
        <default class="visual_es">
            <geom contype="0" conaffinity="0" group="1" type="mesh" rgba="0.4 0.5 0.5 0.1"/>
        </default>
        <joint damping="0.01" armature="0.01"/>
        <geom contype="1" conaffinity="1" friction="1.0 0.3 0.3" rgba="0.5 0.6 0.7 0" margin="0.001" group="0"/>
    </default>
    <visual>
        <rgba com="0.502 1.0 0 1.0" contactpoint="0.5 0.1 0.8 0.4" contactforce="0.2 0.98 0.2 0.8"/>
        <scale com="0.2" forcewidth="0.05" contactwidth="0.10" contactheight="0.04"/>
    </visual>

    <asset>
        <mesh name="trunk" file="trunk.stl"/>
        <mesh name="hip" file="hip.stl"/>
        <mesh name="thigh_mirror" file="thigh_mirror.stl"/>
        <mesh name="calf" file="calf.stl"/>
        <mesh name="thigh" file="thigh.stl"/>
        <hfield name="height_map" nrow="160" ncol="1050" size="6.5 1.6 3 0.1"/>
    </asset>

    <asset>
        <texture type="skybox" builtin="gradient" width="512" height="512" rgb1="1.0 1.0 1.0" rgb2="1.0 1.0 1.0"/>
        <texture name="plane" type="2d" builtin="flat" rgb1="1 1 1" rgb2="1 1 1" width="512" height="512" mark="cross" markrgb="0 0 0"/>
        <material name="plane" reflectance="0.0" texture="plane" texrepeat="3 3" texuniform="true"/>
        <material name="matgeom" reflectance="0.0"/>
    </asset>
    <option timestep="0.001"/>


    <worldbody>
        <geom name="floor" pos="0 0 0" euler="0 0 0" size="0 0 1" type="plane" material="plane" condim="3" conaffinity="1" contype="1" rgba="1 1 1 1"/>
        <!-- <geom name="terrain" pos="0 0 -0.0002" euler="0 0 0" size="0 0 1" type="hfield" material="plane" hfield="height_map" rgba="0 0.0 1.0 1"/> -->
        <light directional="true" diffuse=".8 .8 .8" pos="0 0 10" dir="0 0 -10"/>
        <camera name="track" mode="trackcom" pos="0 -2.3 1.6" xyaxes="1 0 0 0 0.707 0.707"/>
        <!--        <light directional="false" diffuse=".2 .2 .2" specular="0 0 0" pos="0 0 5" dir="0 0 -1" castshadow="false"/>-->

        <body name="trunk" pos="0 0 0.6">
            <inertial pos="0.00846406 0.00404455 -0.000762916" quat="-3.12625e-05 0.708321 0.00247254 0.705886" mass="9.042" diaginertia="0.174706 0.161175 0.033357"/>
            <joint type="free"/>
            <geom class="visual" mesh="trunk"/>
            <geom size="0.18 0.075 0.056" type="box" rgba="0.2 0.2 0.2 0"/>
            <geom size="0.0005 0.0005 0.0005" type="box" contype="0" conaffinity="0" group="1" rgba="0.8 0 0 0"/>
            <geom size="0.0005 0.0005 0.0005" type="box" rgba="0.8 0 0 0"/>
            <site name="imu" pos="0 0 0"/>

            <body name="FL_hip" pos="0.2399 0.051 0">
                <inertial pos="-0.022191 0.015144 -1.5e-05" quat="-0.0135493 0.706835 0.0117635 0.707151" mass="0.1993" diaginertia="0.00558695 0.00491009 0.00290132"/>
                <joint name="FL_hip_joint" pos="0 0 0" axis="1 0 0" limited="true" range="-1.22173 1.22173"/>
                <geom class="visual" mesh="hip"/>
                <geom size="0.046 0.0209" pos="0 0.083 0" quat="0.707107 0.707107 0 0" type="cylinder" rgba="0.2 0.2 0.2 0"/>
                <body name="FL_thigh" pos="0 0.083 0">
                    <inertial pos="-0.005607 -0.003877 -0.048199" quat="0.717987 -0.031246 -0.0335669 0.694544" mass="0.0639" diaginertia="0.0058474 0.00571186 0.000324584"/>
                    <joint name="FL_thigh_joint" pos="0 0 0" axis="0 1 0"/>
                    <geom class="visual" mesh="thigh"/>
                    <geom size="0.125 0.0187 0.0215" pos="0 0 -0.125" quat="0.707107 0 0.707107 0" type="box" rgba="0.2 0.2 0.2 0"/>
                    <body name="FL_calf" pos="0 0 -0.25">
                        <inertial pos="0.00215606 4.88427e-05 -0.166671" quat="0.707462 0.00517582 0.00535172 0.706712" mass="0.0267" diaginertia="0.00690975 0.00689712 5.4885e-05"/>
                        <joint name="FL_calf_joint" pos="0 0 0" axis="0 1 0" limited="true" range="-2.77507 -0.645772"/>
                        <geom type="mesh" contype="0" conaffinity="0" group="1" rgba="0 0 0 1" mesh="calf"/>
                        <geom size="0.125 0.0104 0.008" pos="0 0 -0.125" quat="0.707107 0 0.707107 0" type="box" rgba="0 0 0 0"/>
                        <geom name="fl_foot" size="0.0165" pos="0 0 -0.25" contype="0" conaffinity="0" group="1" rgba="0 0 0 1"/>
                        <geom size="0.0255" pos="0 0 -0.25" rgba="0 0 0 1"/>
                        <site name="fl_tc" size="0.0265" pos="0 0 -0.25" rgba="0 1 0 1"/>

                    </body>
                </body>
            </body>

            <body name="FR_hip" pos="0.2399 -0.051 0">
                <inertial pos="-0.022191 -0.015144 -1.5e-05" quat="0.0135493 0.706835 -0.0117635 0.707151" mass="0.1993" diaginertia="0.00558695 0.00491009 0.00290132"/>
                <joint name="FR_hip_joint" pos="0 0 0" axis="1 0 0" limited="true" range="-1.22173 1.22173"/>
                <geom quat="0 1 0 0" class="visual" mesh="hip"/>
                <geom size="0.046 0.0209" pos="0 -0.083 0" quat="0.707107 0.707107 0 0" type="cylinder" rgba="0.2 0.2 0.2 0"/>
                <body name="FR_thigh" pos="0 -0.083 0">
                    <inertial pos="-0.005607 0.003877 -0.048199" quat="0.694544 -0.0335669 -0.031246 0.717987" mass="0.0639" diaginertia="0.0058474 0.00571186 0.000324584"/>
                    <joint name="FR_thigh_joint" pos="0 0 0" axis="0 1 0"/>
                    <geom class="visual" mesh="thigh_mirror"/>
                    <geom size="0.125 0.0187 0.0215" pos="0 0 -0.125" quat="0.707107 0 0.707107 0" type="box" rgba="0.2 0.2 0.2 0"/>
                    <body name="FR_calf" pos="0 0 -0.25">
                        <inertial pos="0.00215606 4.88427e-05 -0.166671" quat="0.707462 0.00517582 0.00535172 0.706712" mass="0.0267" diaginertia="0.00690975 0.00689712 5.4885e-05"/>
                        <joint name="FR_calf_joint" pos="0 0 0" axis="0 1 0" limited="true" range="-2.77507 -0.645772"/>
                        <geom type="mesh" contype="0" conaffinity="0" group="1" rgba="0 0 0 1" mesh="calf"/>
                        <geom size="0.125 0.0104 0.008" pos="0 0 -0.125" quat="0.707107 0 0.707107 0" type="box" rgba="0 0 0 0"/>
                        <geom name="fr_foot" size="0.0165" pos="0 0 -0.25" contype="0" conaffinity="0" group="1" rgba="0 0 0 1"/>
                        <geom size="0.0255" pos="0 0 -0.25" rgba="0 0 0 1"/>
                        <site name="fr_tc" size="0.0265" pos="0 0 -0.25" rgba="0 1 0 1"/>

                    </body>
                </body>
            </body>

            <body name="RL_hip" pos="-0.2399 0.051 0">
                <inertial pos="0.022191 0.015144 -1.5e-05" quat="0.0117635 0.707151 -0.0135493 0.706835" mass="0.1993" diaginertia="0.00558695 0.00491009 0.00290132"/>
                <joint name="RL_hip_joint" pos="0 0 0" axis="1 0 0" limited="true" range="-1.22173 1.22173"/>
                <geom quat="0 0 1 0" class="visual" mesh="hip"/>
                <geom size="0.046 0.0209" pos="0 0.083 0" quat="0.707107 0.707107 0 0" type="cylinder" rgba="0.2 0.2 0.2 0"/>
                <body name="RL_thigh" pos="0 0.083 0">
                    <inertial pos="-0.005607 -0.003877 -0.048199" quat="0.717987 -0.031246 -0.0335669 0.694544" mass="0.0639" diaginertia="0.0058474 0.00571186 0.000324584"/>
                    <joint name="RL_thigh_joint" pos="0 0 0" axis="0 1 0"/>
                    <geom class="visual" mesh="thigh"/>
                    <geom size="0.125 0.0187 0.0215" pos="0 0 -0.125" quat="0.707107 0 0.707107 0" type="box" rgba="0.2 0.2 0.2 0"/>
                    <body name="RL_calf" pos="0 0 -0.25">
                        <inertial pos="0.00215606 4.88427e-05 -0.166671" quat="0.707462 0.00517582 0.00535172 0.706712" mass="0.0267" diaginertia="0.00690975 0.00689712 5.4885e-05"/>
                        <joint name="RL_calf_joint" pos="0 0 0" axis="0 1 0" limited="true" range="-2.77507 -0.645772"/>
                        <geom type="mesh" contype="0" conaffinity="0" group="1" rgba="0 0 0 1" mesh="calf"/>
                        <geom size="0.125 0.0104 0.008" pos="0 0 -0.125" quat="0.707107 0 0.707107 0" type="box" rgba="0 0 0 0"/>
                        <geom name="rl_foot" size="0.0165" pos="0 0 -0.25" contype="0" conaffinity="0" group="1" rgba="0 0 0 1"/>
                        <geom size="0.0255" pos="0 0 -0.25" rgba="0 0 0 1"/>
                        <site name="rl_tc" size="0.0265" pos="0 0 -0.25" rgba="0 1 0 1"/>

                    </body>
                </body>
            </body>

            <body name="RR_hip" pos="-0.2399 -0.051 0">
                <inertial pos="0.022191 -0.015144 -1.5e-05" quat="-0.0117635 0.707151 0.0135493 0.706835" mass="0.1993" diaginertia="0.00558695 0.00491009 0.00290132"/>
                <joint name="RR_hip_joint" pos="0 0 0" axis="1 0 0" limited="true" range="-1.22173 1.22173"/>
                <geom quat="0 0 0 -1" class="visual" mesh="hip"/>
                <geom size="0.046 0.0209" pos="0 -0.083 0" quat="0.707107 0.707107 0 0" type="cylinder" rgba="0.2 0.2 0.2 0"/>
                <body name="RR_thigh" pos="0 -0.083 0">
                    <inertial pos="-0.005607 0.003877 -0.048199" quat="0.694544 -0.0335669 -0.031246 0.717987" mass="0.0639" diaginertia="0.0058474 0.00571186 0.000324584"/>
                    <joint name="RR_thigh_joint" pos="0 0 0" axis="0 1 0"/>
                    <geom class="visual" mesh="thigh_mirror"/>
                    <geom size="0.125 0.0187 0.0215" pos="0 0 -0.125" quat="0.707107 0 0.707107 0" type="box" rgba="0.2 0.2 0.2 0"/>
                    <body name="RR_calf" pos="0 0 -0.25">
                        <inertial pos="0.00215606 4.88427e-05 -0.166671" quat="0.707462 0.00517582 0.00535172 0.706712" mass="0.0267" diaginertia="0.00690975 0.00689712 5.4885e-05"/>
                        <joint name="RR_calf_joint" pos="0 0 0" axis="0 1 0" limited="true" range="-2.77507 -0.645772"/>
                        <geom type="mesh" contype="0" conaffinity="0" group="1" rgba="0 0 0 1" mesh="calf"/>
                        <geom size="0.125 0.0104 0.008" pos="0 0 -0.125" quat="0.707107 0 0.707107 0" type="box" rgba="0 0 0 0"/>
                        <geom name="rr_foot" size="0.0165" pos="0 0 -0.25" contype="0" conaffinity="0" group="1" rgba="0 0 0 1"/>
                        <geom size="0.0255" pos="0 0 -0.25" rgba="0 0 0 1"/>
                        <site name="rr_tc" size="0.0265" pos="0 0 -0.25" rgba="0 1 0 1"/>
                    </body>
                </body>
            </body>
        </body>

        <!-- <body name="staircase" pos="3.45 3 0" euler="0 0 0">
            <inertial pos="0 0 0" quat="0 0 0 1" mass="1" diaginertia="0.033260231 0.16117211 0.17460442"/>
            <geom contype="1" condim="3" friction="0.7 0.005 0.0001" type="box" pos="0 0 0.075" size="0.15 2 0.075" rgba="0 0.0 1.0 1"/>
            <geom contype="1" condim="3" friction="0.7 0.005 0.0001" type="box" pos="0.30 0 0.15" size="0.15 2 0.15" rgba="0.9 0.9 0.9 1.0"/>
            <geom contype="1" condim="3" friction="0.7 0.005 0.0001" type="box" pos="0.60 0 0.225" size="0.15 2 0.225" rgba="0.9 0.9 0.9 1.0"/>
            <geom contype="1" condim="3" friction="0.7 0.005 0.0001" type="box" pos="0.90 0 0.3" size="0.15 2 0.3" rgba="0.9 0.9 0.9 1.0"/>
            <geom contype="1" condim="3" friction="0.7 0.005 0.0001" type="box" pos="1.20 0 0.375" size="0.15 2 0.375" rgba="0.9 0.9 0.9 1.0"/>
            <geom contype="1" condim="3" friction="0.7 0.005 0.0001" type="box" pos="1.5 0 0.45" size="0.15 2 0.45" rgba="0.9 0.9 0.9 1.0"/>
            <geom contype="1" condim="3" friction="0.7 0.005 0.0001" type="box" pos="1.8 0 0.525" size="0.15 2 0.525" rgba="0.9 0.9 0.9 1.0"/>
            <geom contype="1" condim="3" friction="0.7 0.005 0.0001" type="box" pos="2.1 0 0.6" size="0.15 2 0.6" rgba="0.9 0.9 0.9 1.0"/>
            <geom contype="1" condim="3" friction="0.7 0.005 0.0001" type="box" pos="2.4 0 0.675" size="0.15 2 0.675" rgba="0.9 0.9 0.9 1.0"/>
            <geom contype="1" condim="3" friction="0.7 0.005 0.0001" type="box" pos="2.7 0 0.75" size="0.15 2 0.75" rgba="0.9 0.9 0.9 1.0"/>
            <geom contype="1" condim="3" friction="0.7 0.005 0.0001" type="box" pos="3.6 0 0.75" size="0.75 2 0.75" rgba="0.9 0.9 0.9 1.0"/>
        </body>

        <body name="staircase_sym" pos="11.45 3 0" euler="0 0 3.1415926">
            <inertial pos="0 0 0" quat="0 0 0 1" mass="1" diaginertia="0.033260231 0.16117211 0.17460442"/>
            <geom contype="1" condim="3" friction="0.7 0.005 0.0001" type="box" pos="0 0 0.075" size="0.15 2 0.075" rgba="0 0.0 1.0 1"/>
            <geom contype="1" condim="3" friction="0.7 0.005 0.0001" type="box" pos="0.30 0 0.15" size="0.15 2 0.15" rgba="0.9 0.9 0.9 1.0"/>
            <geom contype="1" condim="3" friction="0.7 0.005 0.0001" type="box" pos="0.60 0 0.225" size="0.15 2 0.225" rgba="0.9 0.9 0.9 1.0"/>
            <geom contype="1" condim="3" friction="0.7 0.005 0.0001" type="box" pos="0.90 0 0.3" size="0.15 2 0.3" rgba="0.9 0.9 0.9 1.0"/>
            <geom contype="1" condim="3" friction="0.7 0.005 0.0001" type="box" pos="1.20 0 0.375" size="0.15 2 0.375" rgba="0.9 0.9 0.9 1.0"/>
            <geom contype="1" condim="3" friction="0.7 0.005 0.0001" type="box" pos="1.5 0 0.45" size="0.15 2 0.45" rgba="0.9 0.9 0.9 1.0"/>
            <geom contype="1" condim="3" friction="0.7 0.005 0.0001" type="box" pos="1.8 0 0.525" size="0.15 2 0.525" rgba="0.9 0.9 0.9 1.0"/>
            <geom contype="1" condim="3" friction="0.7 0.005 0.0001" type="box" pos="2.1 0 0.6" size="0.15 2 0.6" rgba="0.9 0.9 0.9 1.0"/>
            <geom contype="1" condim="3" friction="0.7 0.005 0.0001" type="box" pos="2.4 0 0.675" size="0.15 2 0.675" rgba="0.9 0.9 0.9 1.0"/>
            <geom contype="1" condim="3" friction="0.7 0.005 0.0001" type="box" pos="2.7 0 0.75" size="0.15 2 0.75" rgba="0.9 0.9 0.9 1.0"/>
            <geom contype="1" condim="3" friction="0.7 0.005 0.0001" type="box" pos="3.6 0 0.75" size="0.75 2 0.75" rgba="0.9 0.9 0.9 1.0"/>
        </body> -->
<!-- 
        <body name="staircase" pos="3.45 3 0" euler="0 0 0">
            <inertial pos="0 0 0" quat="0 0 0 1" mass="1" diaginertia="0.033260231 0.16117211 0.17460442"/>
            <geom contype="1" condim="3" friction="0.7 0.005 0.0001" type="box" pos="0 0 0.0475" size="0.15 2 0.045" rgba="0.9 0.9 0.9 1.0"/>
            <geom contype="1" condim="3" friction="0.7 0.005 0.0001" type="box" pos="0.30 0 0.09" size="0.15 2 0.09" rgba="0.9 0.9 0.9 1.0"/>
            <geom contype="1" condim="3" friction="0.7 0.005 0.0001" type="box" pos="0.60 0 0.135" size="0.15 2 0.135" rgba="0.9 0.9 0.9 1.0"/>
            <geom contype="1" condim="3" friction="0.7 0.005 0.0001" type="box" pos="0.90 0 0.18" size="0.15 2 0.18" rgba="0.9 0.9 0.9 1.0"/>
            <geom contype="1" condim="3" friction="0.7 0.005 0.0001" type="box" pos="1.20 0 0.225" size="0.15 2 0.225" rgba="0.9 0.9 0.9 1.0"/>
            <geom contype="1" condim="3" friction="0.7 0.005 0.0001" type="box" pos="1.5 0 0.27" size="0.15 2 0.27" rgba="0.9 0.9 0.9 1.0"/>
            <geom contype="1" condim="3" friction="0.7 0.005 0.0001" type="box" pos="1.8 0 0.315" size="0.15 2 0.315" rgba="0.9 0.9 0.9 1.0"/>
            <geom contype="1" condim="3" friction="0.7 0.005 0.0001" type="box" pos="2.1 0 0.36" size="0.15 2 0.36" rgba="0.9 0.9 0.9 1.0"/>
            <geom contype="1" condim="3" friction="0.7 0.005 0.0001" type="box" pos="2.4 0 0.405" size="0.15 2 0.405" rgba="0.9 0.9 0.9 1.0"/>
            <geom contype="1" condim="3" friction="0.7 0.005 0.0001" type="box" pos="2.7 0 0.45" size="0.15 2 0.45" rgba="0.9 0.9 0.9 1.0"/>
            <geom contype="1" condim="3" friction="0.7 0.005 0.0001" type="box" pos="3.6 0 0.45" size="0.75 2 0.45" rgba="0.9 0.9 0.9 1.0"/>
        </body>

         <body name="staircase_sym" pos="11.45 3 0" euler="0 0 3.1415926">
            <inertial pos="0 0 0" quat="0 0 0 1" mass="1" diaginertia="0.033260231 0.16117211 0.17460442"/>
            <geom contype="1" condim="3" friction="0.7 0.005 0.0001" type="box" pos="0 0 0.0475" size="0.15 2 0.045" rgba="0.9 0.9 0.9 1.0"/>
            <geom contype="1" condim="3" friction="0.7 0.005 0.0001" type="box" pos="0.30 0 0.09" size="0.15 2 0.09" rgba="0.9 0.9 0.9 1.0"/>
            <geom contype="1" condim="3" friction="0.7 0.005 0.0001" type="box" pos="0.60 0 0.135" size="0.15 2 0.135" rgba="0.9 0.9 0.9 1.0"/>
            <geom contype="1" condim="3" friction="0.7 0.005 0.0001" type="box" pos="0.90 0 0.18" size="0.15 2 0.18" rgba="0.9 0.9 0.9 1.0"/>
            <geom contype="1" condim="3" friction="0.7 0.005 0.0001" type="box" pos="1.20 0 0.225" size="0.15 2 0.225" rgba="0.9 0.9 0.9 1.0"/>
            <geom contype="1" condim="3" friction="0.7 0.005 0.0001" type="box" pos="1.5 0 0.27" size="0.15 2 0.27" rgba="0.9 0.9 0.9 1.0"/>
            <geom contype="1" condim="3" friction="0.7 0.005 0.0001" type="box" pos="1.8 0 0.315" size="0.15 2 0.315" rgba="0.9 0.9 0.9 1.0"/>
            <geom contype="1" condim="3" friction="0.7 0.005 0.0001" type="box" pos="2.1 0 0.36" size="0.15 2 0.36" rgba="0.9 0.9 0.9 1.0"/>
            <geom contype="1" condim="3" friction="0.7 0.005 0.0001" type="box" pos="2.4 0 0.405" size="0.15 2 0.405" rgba="0.9 0.9 0.9 1.0"/>
            <geom contype="1" condim="3" friction="0.7 0.005 0.0001" type="box" pos="2.7 0 0.45" size="0.15 2 0.45" rgba="0.9 0.9 0.9 1.0"/>
            <geom contype="1" condim="3" friction="0.7 0.005 0.0001" type="box" pos="3.6 0 0.45" size="0.75 2 0.45" rgba="0.9 0.9 0.9 1.0"/>
        </body> -->

    </worldbody>

    <actuator>
        <motor name="FL_hip" gear="1" joint="FL_hip_joint"/>
        <motor name="FL_thigh" gear="1" joint="FL_thigh_joint"/>
        <motor name="FL_calf" gear="1" joint="FL_calf_joint"/>
        <motor name="FR_hip" gear="1" joint="FR_hip_joint"/>
        <motor name="FR_thigh" gear="1" joint="FR_thigh_joint"/>
        <motor name="FR_calf" gear="1" joint="FR_calf_joint"/>
        <motor name="RL_hip" gear="1" joint="RL_hip_joint"/>
        <motor name="RL_thigh" gear="1" joint="RL_thigh_joint"/>
        <motor name="RL_calf" gear="1" joint="RL_calf_joint"/>
        <motor name="RR_hip" gear="1" joint="RR_hip_joint"/>
        <motor name="RR_thigh" gear="1" joint="RR_thigh_joint"/>
        <motor name="RR_calf" gear="1" joint="RR_calf_joint"/>
    </actuator>

    <sensor>
        <framequat name="Body_Quat" objtype="site" objname="imu"/>
        <gyro name="Body_Gyro" site="imu"/>
        <accelerometer name="Body_Acc" site="imu"/>

        <jointpos name="FL_hip_pos" joint="FL_hip_joint"/>
        <jointpos name="FL_thigh_pos" joint="FL_thigh_joint"/>
        <jointpos name="FL_calf_pos" joint="FL_calf_joint"/>
        <jointpos name="FR_hip_pos" joint="FR_hip_joint"/>
        <jointpos name="FR_thigh_pos" joint="FR_thigh_joint"/>
        <jointpos name="FR_calf_pos" joint="FR_calf_joint"/>
        <jointpos name="RL_hip_pos" joint="RL_hip_joint"/>
        <jointpos name="RL_thigh_pos" joint="RL_thigh_joint"/>
        <jointpos name="RL_calf_pos" joint="RL_calf_joint"/>
        <jointpos name="RR_hip_pos" joint="RR_hip_joint"/>
        <jointpos name="RR_thigh_pos" joint="RR_thigh_joint"/>
        <jointpos name="RR_calf_pos" joint="RR_calf_joint"/>

        <jointvel name="FL_hip_vel" joint="FL_hip_joint"/>
        <jointvel name="FL_thigh_vel" joint="FL_thigh_joint"/>
        <jointvel name="FL_calf_vel" joint="FL_calf_joint"/>
        <jointvel name="FR_hip_vel" joint="FR_hip_joint"/>
        <jointvel name="FR_thigh_vel" joint="FR_thigh_joint"/>
        <jointvel name="FR_calf_vel" joint="FR_calf_joint"/>
        <jointvel name="RL_hip_vel" joint="RL_hip_joint"/>
        <jointvel name="RL_thigh_vel" joint="RL_thigh_joint"/>
        <jointvel name="RL_calf_vel" joint="RL_calf_joint"/>
        <jointvel name="RR_hip_vel" joint="RR_hip_joint"/>
        <jointvel name="RR_thigh_vel" joint="RR_thigh_joint"/>
        <jointvel name="RR_calf_vel" joint="RR_calf_joint"/>

        <touch name="fl_touch" site="fl_tc"/>
        <touch name="fr_touch" site="fr_tc"/>
        <touch name="rl_touch" site="rl_tc"/>
        <touch name="rr_touch" site="rr_tc"/>
    </sensor>

</mujoco>
